Workbook

Sheet Static
A1: Performance Fee Distribution Framework
A2: Athanase Industrial Partner — real roles, salaries & performance weights (source: Compensation.xlsx › Static). Amounts in millions.
A4: 1. Global assumptions (edit the gold cells)
A5: Performance-fee rate (of profits) | F5: 0.2
A6: Firm take rate — share of perf-fee to the comp pool | F6: 0.6
A7: Assumed gross return on AUM | F7: 0.12
A8: Management fee (of AUM) | F8: 0.015
A9: AUM tier threshold (millions) | F9: 300
A10: Employer cost loading on salary | F10: 1.62
A11: Comp pool = AUM × return × fee rate × take rate. (The firm retains the other 40% of the performance fee.)
A13: 2. AUM scenarios & performance-fee economics (millions)
A14: Metric | H14: Scenario 1 | I14: Scenario 2 | J14: Scenario 3 | K14: Scenario 4 | L14: Scenario 5 | M14: Scenario 6
A15: AUM (millions) | H15: 20 | I15: 300 | J15: 500 | K15: 1000 | L15: 2000 | M15: 5000
A16: Gross profit (= AUM × return) | H16: =H15*$F$7 | I16: =I15*$F$7 | J16: =J15*$F$7 | K16: =K15*$F$7 | L16: =L15*$F$7 | M16: =M15*$F$7
A17: Performance fee (= profit × fee rate) | H17: =H16*$F$5 | I17: =I16*$F$5 | J17: =J16*$F$5 | K17: =K16*$F$5 | L17: =L16*$F$5 | M17: =M16*$F$5
A18: Comp pool (= perf fee × take rate) | H18: =H17*$F$6 | I18: =I17*$F$6 | J18: =J17*$F$6 | K18: =K17*$F$6 | L18: =L17*$F$6 | M18: =M17*$F$6
A20: 3. Organisation, weights & headcount | B20: Salary < $300m | C20: Salary ≥ $300m | D20: Performance weight | G20: Headcount → | H20: @ $20m | I20: @ $300m | J20: @ $500m | K20: @ $1,000m | L20: @ $2,000m | M20: @ $5,000m
A21: CIO | B21: 0.2 | C21: 0.3 | D21: 16 | H21: 1 | I21: 1 | J21: 1 | K21: 1 | L21: 1 | M21: 1
A22: PM | B22: 0.13 | C22: 0.2 | D22: 8 | H22: 2 | I22: 2 | J22: 3 | K22: 3 | L22: 4 | M22: 4
A23: Junior PM | B23: 0.1 | C23: 0.2 | D23: 6 | H23: 0 | I23: 0 | J23: 1 | K23: 1 | L23: 2 | M23: 2
A24: Senior Analyst | B24: 0.05 | C24: 0.2 | D24: 4 | H24: 0 | I24: 1 | J24: 1 | K24: 2 | L24: 3 | M24: 3
A25: Analyst | B25: 0 | C25: 0.2 | D25: 2.5 | H25: 0 | I25: 2 | J25: 3 | K25: 4 | L25: 8 | M25: 8
A26: CEO | B26: 0.15 | C26: 0.3 | D26: 8 | H26: 1 | I26: 1 | J26: 1 | K26: 1 | L26: 1 | M26: 1
A27: CFO | B27: 0.1 | C27: 0.15 | D27: 3 | H27: 0.2 | I27: 0.2 | J27: 0.2 | K27: 1 | L27: 1 | M27: 1
A28: COO | B28: 0.12 | C28: 0.2 | D28: 3 | H28: 0.5 | I28: 0.5 | J28: 0.5 | K28: 1 | L28: 1 | M28: 1
A29: IR | B29: 0.12 | C29: 0.12 | D29: 1 | H29: 1 | I29: 2 | J29: 2 | K29: 2 | L29: 2 | M29: 2
A30: Support | B30: 0.12 | C30: 0.12 | D30: 1 | H30: 0.5 | I30: 0.5 | J30: 0.5 | K30: 1 | L30: 1 | M30: 1
A31: Execution | B31: 0 | C31: 0.2 | D31: 2 | H31: 0 | I31: 0 | J31: 0 | K31: 1 | L31: 1 | M31: 1
A32: Risk | B32: 0 | C32: 0.2 | D32: 2 | H32: 0 | I32: 0 | J32: 0 | K32: 1 | L32: 1 | M32: 1
A33: Compliance | B33: 0 | C33: 0.2 | D33: 1 | H33: 0 | I33: 0 | J33: 0 | K33: 1 | L33: 1 | M33: 1
A34: Total performance units | G34: Σ weight×HC → | H34: =SUMPRODUCT($D$21:$D$33,H21:H33) | I34: =SUMPRODUCT($D$21:$D$33,I21:I33) | J34: =SUMPRODUCT($D$21:$D$33,J21:J33) | K34: =SUMPRODUCT($D$21:$D$33,K21:K33) | L34: =SUMPRODUCT($D$21:$D$33,L21:L33) | M34: =SUMPRODUCT($D$21:$D$33,M21:M33)
A35: Value per performance unit (millions) | G35: pool ÷ units → | H35: =IF(H34=0,0,H18/H34) | I35: =IF(I34=0,0,I18/I34) | J35: =IF(J34=0,0,J18/J34) | K35: =IF(K34=0,0,K18/K34) | L35: =IF(L34=0,0,L18/L34) | M35: =IF(M34=0,0,M18/M34)
A36: Total fixed payroll, loaded (millions) | H36: =IF(H15<$F$9,SUMPRODUCT($B$21:$B$33,H21:H33),SUMPRODUCT($C$21:$C$33,H21:H33))*$F$10 | I36: =IF(I15<$F$9,SUMPRODUCT($B$21:$B$33,I21:I33),SUMPRODUCT($C$21:$C$33,I21:I33))*$F$10 | J36: =IF(J15<$F$9,SUMPRODUCT($B$21:$B$33,J21:J33),SUMPRODUCT($C$21:$C$33,J21:J33))*$F$10 | K36: =IF(K15<$F$9,SUMPRODUCT($B$21:$B$33,K21:K33),SUMPRODUCT($C$21:$C$33,K21:K33))*$F$10 | L36: =IF(L15<$F$9,SUMPRODUCT($B$21:$B$33,L21:L33),SUMPRODUCT($C$21:$C$33,L21:L33))*$F$10 | M36: =IF(M15<$F$9,SUMPRODUCT($B$21:$B$33,M21:M33),SUMPRODUCT($C$21:$C$33,M21:M33))*$F$10
A37: Total headcount | H37: =SUM(H21:H33) | I37: =SUM(I21:I33) | J37: =SUM(J21:J33) | K37: =SUM(K21:K33) | L37: =SUM(L21:L33) | M37: =SUM(M21:M33)
A39: 4. Performance payout PER PERSON, by scenario (millions — absolute, grows with AUM)
A40: Role | D40: Weight | H40: @ $20m | I40: @ $300m | J40: @ $500m | K40: @ $1,000m | L40: @ $2,000m | M40: @ $5,000m
A41: =A21 | D41: =D21 | H41: =$D21*H$35 | I41: =$D21*I$35 | J41: =$D21*J$35 | K41: =$D21*K$35 | L41: =$D21*L$35 | M41: =$D21*M$35
A42: =A22 | D42: =D22 | H42: =$D22*H$35 | I42: =$D22*I$35 | J42: =$D22*J$35 | K42: =$D22*K$35 | L42: =$D22*L$35 | M42: =$D22*M$35
A43: =A23 | D43: =D23 | H43: =$D23*H$35 | I43: =$D23*I$35 | J43: =$D23*J$35 | K43: =$D23*K$35 | L43: =$D23*L$35 | M43: =$D23*M$35
A44: =A24 | D44: =D24 | H44: =$D24*H$35 | I44: =$D24*I$35 | J44: =$D24*J$35 | K44: =$D24*K$35 | L44: =$D24*L$35 | M44: =$D24*M$35
...

Sheet Take by AUM
A1: Each role's share of the take as AUM grows $100m → $2bn
A2: Share = role weight × headcount ÷ total weighted units. Real weights from Compensation.xlsx. Columns sum to 100%.
A4: AUM (millions) → | B4: 100 | C4: 200 | D4: 300 | E4: 400 | F4: 500 | G4: 600 | H4: 700 | I4: 800 | J4: 900 | K4: 1000 | L4: 1100 | M4: 1200 | N4: 1300 | O4: 1400 | P4: 1500 | Q4: 1600 | R4: 1700 | S4: 1800 | T4: 1900 | U4: 2000
A5: CIO (wt 16) | B5: 0.34440344 | C5: 0.31981725 | D5: 0.29850746 | E5: 0.25869038 | F5: 0.22824536 | G5: 0.21834061 | H5: 0.20925974 | I5: 0.20090407 | J5: 0.19319005 | K5: 0.18604651 | L5: 0.18018018 | M5: 0.17467249 | N5: 0.16949153 | O5: 0.16460905 | P5: 0.16 | Q5: 0.15564202 | R5: 0.15151515 | S5: 0.14760148 | T5: 0.14388489 | U5: 0.14035088
A6: PM (wt 8) | B6: 0.34440344 | C6: 0.31981725 | D6: 0.29850746 | E6: 0.32336297 | F6: 0.34236805 | G6: 0.32751092 | H6: 0.31388962 | I6: 0.3013561 | J6: 0.28978508 | K6: 0.27906977 | L6: 0.27927928 | M6: 0.27947598 | N6: 0.27966102 | O6: 0.27983539 | P6: 0.28 | Q6: 0.28015564 | R6: 0.28030303 | S6: 0.2804428 | T6: 0.28057554 | U6: 0.28070175
A7: Junior PM (wt 6) | B7: 0 | C7: 0 | D7: 0 | E7: 0.048504446 | F7: 0.085592011 | G7: 0.081877729 | H7: 0.078472404 | I7: 0.075339026 | J7: 0.072446269 | K7: 0.069767442 | L7: 0.074324324 | M7: 0.07860262 | N7: 0.082627119 | O7: 0.086419753 | P7: 0.09 | Q7: 0.093385214 | R7: 0.096590909 | S7: 0.099630996 | T7: 0.10251799 | U7: 0.10526316
A8: Senior Analyst (wt 4) | B8: 0.024600246 | C8: 0.0513992 | D8: 0.074626866 | E8: 0.064672595 | F8: 0.057061341 | G8: 0.065502183 | H8: 0.07324091 | I8: 0.080361627 | J8: 0.086935523 | K8: 0.093023256 | L8: 0.094594595 | M8: 0.096069869 | N8: 0.097457627 | O8: 0.098765432 | P8: 0.1 | Q8: 0.10116732 | R8: 0.10227273 | S8: 0.10332103 | T8: 0.10431655 | U8: 0.10526316
A9: Analyst (wt 2.5) | B9: 0.030750308 | C9: 0.064249001 | D9: 0.093283582 | E9: 0.10105093 | F9: 0.10699001 | G9: 0.10917031 | H9: 0.11116924 | I9: 0.11300854 | J9: 0.11470659 | K9: 0.11627907 | L9: 0.12387387 | M9: 0.13100437 | N9: 0.13771186 | O9: 0.14403292 | P9: 0.15 | Q9: 0.15564202 | R9: 0.16098485 | S9: 0.16605166 | T9: 0.17086331 | U9: 0.1754386
A10: CEO (wt 8) | B10: 0.17220172 | C10: 0.15990862 | D10: 0.14925373 | E10: 0.12934519 | F10: 0.11412268 | G10: 0.10917031 | H10: 0.10462987 | I10: 0.10045203 | J10: 0.096595025 | K10: 0.093023256 | L10: 0.09009009 | M10: 0.087336245 | N10: 0.084745763 | O10: 0.082304527 | P10: 0.08 | Q10: 0.077821012 | R10: 0.075757576 | S10: 0.073800738 | T10: 0.071942446 | U10: 0.070175439
A11: CFO (wt 3) | B11: 0.012915129 | C11: 0.011993147 | D11: 0.01119403 | E11: 0.0097008892 | F11: 0.0085592011 | G11: 0.014737991 | H11: 0.020402825 | I11: 0.025615269 | J11: 0.030427433 | K11: 0.034883721 | L11: 0.033783784 | M11: 0.032751092 | N11: 0.031779661 | O11: 0.030864198 | P11: 0.03 | Q11: 0.029182879 | R11: 0.028409091 | S11: 0.027675277 | T11: 0.026978417 | U11: 0.026315789
A12: COO (wt 3) | B12: 0.032287823 | C12: 0.029982867 | D12: 0.027985075 | E12: 0.024252223 | F12: 0.021398003 | G12: 0.024563319 | H12: 0.027465341 | I12: 0.03013561 | J12: 0.032600821 | K12: 0.034883721 | L12: 0.033783784 | M12: 0.032751092 | N12: 0.031779661 | O12: 0.030864198 | P12: 0.03 | Q12: 0.029182879 | R12: 0.028409091 | S12: 0.027675277 | T12: 0.026978417 | U12: 0.026315789
A13: IR (wt 1) | B13: 0.027675277 | C13: 0.032838378 | D13: 0.037313433 | E13: 0.032336297 | F13: 0.02853067 | G13: 0.027292576 | H13: 0.026157468 | I13: 0.025113009 | J13: 0.024148756 | K13: 0.023255814 | L13: 0.022522523 | M13: 0.021834061 | N13: 0.021186441 | O13: 0.020576132 | P13: 0.02 | Q13: 0.019455253 | R13: 0.018939394 | S13: 0.018450185 | T13: 0.017985612 | U13: 0.01754386
A14: Support (wt 1) | B14: 0.010762608 | C14: 0.009994289 | D14: 0.0093283582 | E14: 0.0080840744 | F14: 0.0071326676 | G14: 0.0081877729 | H14: 0.0091551138 | I14: 0.010045203 | J14: 0.01086694 | K14: 0.011627907 | L14: 0.011261261 | M14: 0.010917031 | N14: 0.01059322 | O14: 0.010288066 | P14: 0.01 | Q14: 0.0097276265 | R14: 0.009469697 | S14: 0.0092250923 | T14: 0.0089928058 | U14: 0.0087719298
A15: Execution (wt 2) | B15: 0 | C15: 0 | D15: 0 | E15: 0 | F15: 0 | G15: 0.0054585153 | H15: 0.010462987 | I15: 0.015067805 | J15: 0.019319005 | K15: 0.023255814 | L15: 0.022522523 | M15: 0.021834061 | N15: 0.021186441 | O15: 0.020576132 | P15: 0.02 | Q15: 0.019455253 | R15: 0.018939394 | S15: 0.018450185 | T15: 0.017985612 | U15: 0.01754386
... A17: Compliance (wt 1) | B17: 0 | C17: 0 | D17: 0 | E17: 0 | F17: 0 | G17: 0.0027292576 | H17: 0.0052314936 | I17: 0.0075339026 | J17: 0.0096595025 | K17: 0.011627907 | L17: 0.011261261 | M17: 0.010917031 | N17: 0.01059322 | O17: 0.010288066 | P17: 0.01 | Q17: 0.0097276265 | R17: 0.009469697 | S17: 0.0092250923 | T17: 0.0089928058 | U17: 0.0087719298
A18: Total (check) | B18: =SUM(B5:B17) | C18: =SUM(C5:C17) | D18: =SUM(D5:D17) | E18: =SUM(E5:E17) | F18: =SUM(F5:F17) | G18: =SUM(G5:G17) | H18: =SUM(H5:H17) | I18: =SUM(I5:I17) | ... U18: =SUM(U5:U17)

Sheet Take per Person
A1: Per-person share of the take as AUM grows $100m → $2bn
A2: Per-person share = role weight ÷ total weighted units. One individual's slice; declines for every role as the firm hires.
A4: AUM (millions) → | B4: 100 | C4: 200 | D4: 300 | E4: 400 | F4: 500 | G4: 600 | H4: 700 | I4: 800 | J4: 900 | K4: 1000 | L4: 1100 | M4: 1200 | N4: 1300 | O4: 1400 | P4: 1500 | Q4: 1600 | R4: 1700 | S4: 1800 | T4: 1900 | U4: 2000
A5: CIO (wt 16) | B5: 0.34440344 | C5: 0.31981725 | D5: 0.29850746 | E5: 0.25869038 | F5: 0.22824536 | G5: 0.21834061 | H5: 0.20925974 | I5: 0.20090407 | J5: 0.19319005 | K5: 0.18604651 | L5: 0.18018018 | M5: 0.17467249 | N5: 0.16949153 | O5: 0.16460905 | P5: 0.16 | Q5: 0.15564202 | R5: 0.15151515 | S5: 0.14760148 | T5: 0.14388489 | U5: 0.14035088
A6: PM (wt 8) | B6: 0.17220172 | C6: 0.15990862 | D6: 0.14925373 | E6: 0.12934519 | F6: 0.11412268 | G6: 0.10917031 | H6: 0.10462987 | I6: 0.10045203 | J6: 0.096595025 | K6: 0.093023256 | L6: 0.09009009 | M6: 0.087336245 | N6: 0.084745763 | O6: 0.082304527 | P6: 0.08 | Q6: 0.077821012 | R6: 0.075757576 | S6: 0.073800738 | T6: 0.071942446 | U6: 0.070175439
A7: Junior PM (wt 6) | B7: 0.12915129 | C7: 0.11993147 | D7: 0.1119403 | E7: 0.097008892 | F7: 0.085592011 | G7: 0.081877729 | H7: 0.078472404 | I7: 0.075339026 | J7: 0.072446269 | K7: 0.069767442 | L7: 0.067567568 | M7: 0.065502183 | N7: 0.063559322 | O7: 0.061728395 | P7: 0.06 | Q7: 0.058365759 | R7: 0.056818182 | S7: 0.055350554 | T7: 0.053956835 | U7: 0.052631579
A8: Senior Analyst (wt 4) | B8: 0.086100861 | C8: 0.079954312 | D8: 0.074626866 | E8: 0.064672595 | F8: 0.057061341 | G8: 0.054585153 | H8: 0.052314936 | I8: 0.050226017 | J8: 0.048297513 | K8: 0.046511628 | L8: 0.045045045 | M8: 0.043668122 | N8: 0.042372881 | O8: 0.041152263 | P8: 0.04 | Q8: 0.038910506 | R8: 0.037878788 | S8: 0.036900369 | T8: 0.035971223 | U8: 0.035087719
A9: Analyst (wt 2.5) | B9: 0.053813038 | C9: 0.049971445 | D9: 0.046641791 | E9: 0.040420372 | F9: 0.035663338 | G9: 0.034115721 | H9: 0.032696835 | I9: 0.031391261 | J9: 0.030185945 | K9: 0.029069767 | L9: 0.028153153 | M9: 0.027292576 | N9: 0.026483051 | O9: 0.025720165 | P9: 0.025 | Q9: 0.024319066 | R9: 0.023674242 | S9: 0.023062731 | T9: 0.022482014 | U9: 0.021929825
A10: CEO (wt 8) | B10: 0.17220172 | C10: 0.15990862 | D10: 0.14925373 | E10: 0.12934519 | F10: 0.11412268 | G10: 0.10917031 | H10: 0.10462987 | I10: 0.10045203 | J10: 0.096595025 | K10: 0.093023256 | L10: 0.09009009 | M10: 0.087336245 | N10: 0.084745763 | O10: 0.082304527 | P10: 0.08 | Q10: 0.077821012 | R10: 0.075757576 | S10: 0.073800738 | T10: 0.071942446 | U10: 0.070175439
A11: CFO (wt 3) | B11: 0.064575646 | C11: 0.059965734 | D11: 0.055970149 | E11: 0.048504446 | F11: 0.042796006 | G11: 0.040938865 | H11: 0.039236202 | I11: 0.037669513 | J11: 0.036223135 | K11: 0.034883721 | L11: 0.033783784 | M11: 0.032751092 | N11: 0.031779661 | O11: 0.030864198 | P11: 0.03 | Q11: 0.029182879 | R11: 0.028409091 | S11: 0.027675277 | T11: 0.026978417 | U11: 0.026315789
A12: COO (wt 3) | B12: 0.064575646 | C12: 0.059965734 | D12: 0.055970149 | E12: 0.048504446 | F12: 0.042796006 | G12: 0.040938865 | H12: 0.039236202 | I12: 0.037669513 | J12: 0.036223135 | K12: 0.034883721 | L12: 0.033783784 | M12: 0.032751092 | N12: 0.031779661 | O12: 0.030864198 | P12: 0.03 | Q12: 0.029182879 | R12: 0.028409091 | S12: 0.027675277 | T12: 0.026978417 | U12: 0.026315789
A13: IR (wt 1) | B13: 0.021525215 | C13: 0.019988578 | D13: 0.018656716 | E13: 0.016168149 | F13: 0.014265335 | G13: 0.013646288 | H13: 0.013078734 | I13: 0.012556504 | J13: 0.012074378 | K13: 0.011627907 | L13: 0.011261261 | M13: 0.010917031 | N13: 0.01059322 | O13: 0.010288066 | P13: 0.01 | Q13: 0.0097276265 | R13: 0.009469697 | S13: 0.0092250923 | T13: 0.0089928058 | U13: 0.0087719298
A14: Support (wt 1) | B14: 0.021525215 | C14: 0.019988578 | D14: 0.018656716 | E14: 0.016168149 | F14: 0.014265335 | G14: 0.013646288 | H14: 0.013078734 | I14: 0.012556504 | J14: 0.012074378 | K14: 0.011627907 | L14: 0.011261261 | M14: 0.010917031 | N14: 0.01059322 | O14: 0.010288066 | P14: 0.01 | Q14: 0.0097276265 | R14: 0.009469697 | S14: 0.0092250923 | T14: 0.0089928058 | U14: 0.0087719298
A15: Execution (wt 2) | B15: 0.043050431 | C15: 0.039977156 | D15: 0.037313433 | E15: 0.032336297 | F15: 0.02853067 | G15: 0.027292576 | H15: 0.026157468 | I15: 0.025113009 | J15: 0.024148756 | K15: 0.023255814 | L15: 0.022522523 | M15: 0.021834061 | N15: 0.021186441 | O15: 0.020576132 | P15: 0.02 | Q15: 0.019455253 | R15: 0.018939394 | S15: 0.018450185 | T15: 0.017985612 | U15: 0.01754386
... A18: Total units (denominator) | B18: 46.5 | C18: 50 | D18: 53.6 | E18: 61.9 | F18: 70.1 | G18: 73.3 | H18: 76.5 | I18: 79.6 | J18: 82.8 | K18: 86 | L18: 88.8 | M18: 91.6 | N18: 94.4 | O18: 97.2 | P18: 100 | Q18: 102.8 | R18: 105.6 | S18: 108.4 | T18: 111.2 | U18: 114

Sheet Profit Simulation
A1: Profit simulation by AUM level, with ownership distribution
A2: Firm EBIT = management fee + equity take (40% of perf fee) − operating costs. Distributed to owners. Millions; links to Static.
A4: P&L line (millions) | H4: AUM $20m | I4: AUM $300m | J4: AUM $500m | K4: AUM $1,000m | L4: AUM $2,000m | M4: AUM $5,000m
A5: AUM | H5: =Static!H15 | I5: =Static!I15 | J5: =Static!J15 | K5: =Static!K15 | L5: =Static!L15 | M5: =Static!M15
A6: Management fee (1.5% × AUM) | H6: =Static!H15*Static!$F$8 | I6: =Static!I15*Static!$F$8 | J6: =Static!J15*Static!$F$8 | K6: =Static!K15*Static!$F$8 | L6: =Static!L15*Static!$F$8 | M6: =Static!M15*Static!$F$8
A7: Performance fee (20% × profit) | H7: =Static!H15*Static!$F$7*Static!$F$5 | I7: =Static!I15*Static!$F$7*Static!$F$5 | J7: =Static!J15*Static!$F$7*Static!$F$5 | K7: =Static!K15*Static!$F$7*Static!$F$5 | L7: =Static!L15*Static!$F$7*Static!$F$5 | M7: =Static!M15*Static!$F$7*Static!$F$5
A8: of which team take (60%) → staff | H8: =H7*Static!$F$6 | I8: =I7*Static!$F$6 | J8: =J7*Static!$F$6 | K8: =K7*Static!$F$6 | L8: =L7*Static!$F$6 | M8: =M7*Static!$F$6
A9: of which equity take (40%) → firm | H9: =H7*(1-Static!$F$6) | I9: =I7*(1-Static!$F$6) | J9: =J7*(1-Static!$F$6) | K9: =K7*(1-Static!$F$6) | L9: =L7*(1-Static!$F$6) | M9: =M7*(1-Static!$F$6)
A10: Firm revenue (mgmt fee + equity take) | H10: =H6+H9 | I10: =I6+I9 | J10: =J6+J9 | K10: =K6+K9 | L10: =L6+L9 | M10: =M6+M9
A11: Operating cost: loaded salaries | H11: =Static!H36 | I11: =Static!I36 | J11: =Static!J36 | K11: =Static!K36 | L11: =Static!L36 | M11: =Static!M36
A12: Operating cost: other costs | H12: 0.5 | I12: 1 | J12: 1.5 | K12: 3 | L12: 4.301 | M12: 4.301
A13: Total operating costs | H13: =H11+H12 | I13: =I11+I12 | J13: =J11+J12 | K13: =K11+K12 | L13: =L11+L12 | M13: =M11+M12
A14: EBIT (profit to owners) | H14: =H10-H13 | I14: =I10-I13 | J14: =J10-J13 | K14: =K10-K13 | L14: =L10-L13 | M14: =M10-M13
A15: EBIT margin (on firm revenue) | H15: =IF(H10=0,0,H14/H10) | I15: =IF(I10=0,0,I14/I10) | J15: =IF(J10=0,0,J14/J10) | K15: =IF(K10=0,0,K14/K10) | L15: =IF(L10=0,0,L14/L10) | M15: =IF(M10=0,0,M14/M10)
A17: Ownership distribution of EBIT
A18: CIO | G18: 0.636 | H18: =H14*$G18 | I18: =I14*$G18 | J18: =J14*$G18 | K18: =K14*$G18 | L18: =L14*$G18 | M18: =M14*$G18
A19: Portfolio Manager 1 | G19: 0.1 | H19: =H14*$G19 | I19: =I14*$G19 | J19: =J14*$G19 | K19: =K14*$G19 | L19: =L14*$G19 | M19: =M14*$G19
A20: Portfolio Manager 2 | G20: 0.1 | H20: =H14*$G20 | I20: =I14*$G20 | J20: =J14*$G20 | K20: =K14*$G20 | L20: =L14*$G20 | M20: =M14*$G20
A21: Other owners | G21: 0.164 | H21: =H14*$G21 | I21: =I14*$G21 | J21: =J14*$G21 | K21: =K14*$G21 | L21: =L14*$G21 | M21: =M14*$G21
A22: Total distributed | G22: =SUM(G18:G21) | H22: =SUM(H18:H21) | I22: =SUM(I18:I21) | J22: =SUM(J18:J21) | K22: =SUM(K18:K21) | L22: =SUM(L18:L21) | M22: =SUM(M18:M21)

Sheet Owner Total Comp
A1: Total compensation for equity owners — CIO and the two PMs
A2: Total comp = base salary + performance take (weight × unit value) + equity distribution (ownership × EBIT). Millions.
A4: Component (millions) | H4: AUM $20m | I4: AUM $300m | J4: AUM $500m | K4: AUM $1,000m | L4: AUM $2,000m | M4: AUM $5,000m
A5: CIO (wt 16, equity 63.6%)
A6: Base salary | H6: =IF(Static!H15<Static!$F$9,Static!$B$21,Static!$C$21) | I6: =IF(Static!I15<Static!$F$9,Static!$B$21,Static!$C$21) | J6: =IF(Static!J15<Static!$F$9,Static!$B$21,Static!$C$21) | K6: =IF(Static!K15<Static!$F$9,Static!$B$21,Static!$C$21) | L6: =IF(Static!L15<Static!$F$9,Static!$B$21,Static!$C$21) | M6: =IF(Static!M15<Static!$F$9,Static!$B$21,Static!$C$21)
A7: Performance take (weight × unit value) | H7: =Static!$D$21*Static!H$35 | I7: =Static!$D$21*Static!I$35 | J7: =Static!$D$21*Static!J$35 | K7: =Static!$D$21*Static!K$35 | L7: =Static!$D$21*Static!L$35 | M7: =Static!$D$21*Static!M$35
A8: Equity distribution (63.6% × EBIT) | G8: 0.636 | H8: ='Profit Simulation'!H14*$G8 | I8: ='Profit Simulation'!I14*$G8 | J8: ='Profit Simulation'!J14*$G8 | K8: ='Profit Simulation'!K14*$G8 | L8: ='Profit Simulation'!L14*$G8 | M8: ='Profit Simulation'!M14*$G8
A9: TOTAL COMP — CIO | H9: =SUM(H6:H8) | I9: =SUM(I6:I8) | J9: =SUM(J6:J8) | K9: =SUM(K6:K8) | L9: =SUM(L6:L8) | M9: =SUM(M6:M8)
A11: Portfolio Manager 1 (wt 8, equity 10.0%)
A12: Base salary | H12: =IF(Static!H15<Static!$F$9,Static!$B$22,Static!$C$22) | I12: =IF(Static!I15<Static!$F$9,Static!$B$22,Static!$C$22) | J12: =IF(Static!J15<Static!$F$9,Static!$B$22,Static!$C$22) | K12: =IF(Static!K15<Static!$F$9,Static!$B$22,Static!$C$22) | L12: =IF(Static!L15<Static!$F$9,Static!$B$22,Static!$C$22) | M12: =IF(Static!M15<Static!$F$9,Static!$B$22,Static!$C$22)
A13: Performance take (weight × unit value) | H13: =Static!$D$22*Static!H$35 | I13: =Static!$D$22*Static!I$35 | J13: =Static!$D$22*Static!J$35 | K13: =Static!$D$22*Static!K$35 | L13: =Static!$D$22*Static!L$35 | M13: =Static!$D$22*Static!M$35
A14: Equity distribution (10.0% × EBIT) | G14: 0.1 | H14: ='Profit Simulation'!H14*$G14 | I14: ='Profit Simulation'!I14*$G14 | J14: ='Profit Simulation'!J14*$G14 | K14: ='Profit Simulation'!K14*$G14 | L14: ='Profit Simulation'!L14*$G14 | M14: ='Profit Simulation'!M14*$G14
A15: TOTAL COMP — Portfolio Manager 1 | H15: =SUM(H12:H14) | I15: =SUM(I12:I14) | J15: =SUM(J12:J14) | K15: =SUM(K12:K14) | L15: =SUM(L12:L14) | M15: =SUM(M12:M14)
A17: Portfolio Manager 2 (wt 8, equity 10.0%)
A18: Base salary | H18: =IF(Static!H15<Static!$F$9,Static!$B$22,Static!$C$22) | I18: =IF(Static!I15<Static!$F$9,Static!$B$22,Static!$C$22) | J18: =IF(Static!J15<Static!$F$9,Static!$B$22,Static!$C$22) | K18: =IF(Static!K15<Static!$F$9,Static!$B$22,Static!$C$22) | L18: =IF(Static!L15<Static!$F$9,Static!$B$22,Static!$C$22) | M18: =IF(Static!M15<Static!$F$9,Static!$B$22,Static!$C$22)
A19: Performance take (weight × unit value) | H19: =Static!$D$22*Static!H$35 | I19: =Static!$D$22*Static!I$35 | J19: =Static!$D$22*Static!J$35 | K19: =Static!$D$22*Static!K$35 | L19: =Static!$D$22*Static!L$35 | M19: =Static!$D$22*Static!M$35
A20: Equity distribution (10.0% × EBIT) | G20: 0.1 | H20: ='Profit Simulation'!H14*$G20 | I20: ='Profit Simulation'!I14*$G20 | J20: ='Profit Simulation'!J14*$G20 | K20: ='Profit Simulation'!K14*$G20 | L20: ='Profit Simulation'!L14*$G20 | M20: ='Profit Simulation'!M14*$G20
A21: TOTAL COMP — Portfolio Manager 2 | H21: =SUM(H18:H20) | I21: =SUM(I18:I20) | J21: =SUM(J18:J20) | K21: =SUM(K18:K20) | L21: =SUM(L18:L20) | M21: =SUM(M18:M20)
A23: Both PMs combined (equity 20%) | H23: =H13*2 | I23: =I13*2 | J23: =J13*2 | K23: =K13*2 | L23: =L13*2 | M23: =M13*2
